Workbook

Sheet Dashboard
A1: CAP Scholarship Program — Tracker Dashboard
A3: =CONCATENATE("Last updated: ",TEXT(TODAY(),"DD MMM YYYY"))
A5: Program KPIs
A6: Active Scholarships | C6: At-Risk Recipients | E6: Met Commitment This Week | G6: Total Sessions This Month
A7: =COUNTIF('Recipient Profile'!J:J,"Active") | C7: =COUNTIF('Recipient Profile'!O:O,"Red") | E7: =COUNTIF('Weekly Engagement Log'!K:K,"Yes") | G7: =COUNTA('Session Log'!A:A)-1
A10: Recipients Needing Outreach
A11: Recipient ID | B11: Name | C11: Risk Level | D11: Days Silent | E11: Recommended Action
A12: SCH-003 | B12: Aisha Okonkwo | C12: Red | D12: 16 days silent | E12: Begin withdrawal conversation per agreement clause 3
A13: See Withdrawal Risk Monitor tab for full detail and recommended actions
A17: Upcoming Check-ins Due (Next 7 Days)
A18: Recipient ID | B18: Name | C18: Milestone | D18: Due Date
A19: SCH-002 | B19: Marcus Webb | C19: 60-day check-in | D19: 46174
A20: Check Onboarding & Agreement tab for full milestone tracker
A24: Recipient Status at a Glance
A25: Name | B25: Stage | C25: Risk Level | D25: Days Since Engagement | E25: Engagement Score (Last Week) | F25: Commitment Met?
A26: ='Recipient Profile'!B2 | B26: ='Recipient Profile'!J2 | C26: ='Recipient Profile'!O2 | D26: ='Recipient Profile'!N2 | E26: 4 | F26: Yes
A27: ='Recipient Profile'!B3 | B27: ='Recipient Profile'!J3 | C27: ='Recipient Profile'!O3 | D27: ='Recipient Profile'!N3 | E27: 4 | F27: Yes
A28: ='Recipient Profile'!B4 | B28: ='Recipient Profile'!J4 | C28: ='Recipient Profile'!O4 | D28: ='Recipient Profile'!N4 | E28: 0 | F28: No

Sheet Recipient Profile
A1: Recipient ID | B1: Full Name | C1: Preferred Name | D1: Email | E1: Phone | F1: Scholarship Start Date | G1: Scholarship End Date | H1: Coach Assigned | I1: Application Reason (Summary) | J1: Current Stage | K1: Agreement Signed | L1: Agreement Signed Date | M1: Last Engagement Date | N1: Days Since Last Engagement | O1: Risk Level | P1: Notes (Visible)
A2: SCH-001 | B2: Jane Thompson | C2: Jane | D2: jane.thompson@email.com | E2: 0412 345 678 | F2: 46037 | G2: =IFERROR(F2+180,"") | H2: Sarah Mitchell | I2: Returning to workforce after career break | J2: Active | K2: Yes | L2: 46042 | M2: =IFERROR(MAXIFS('Weekly Engagement Log'!B:B,'Weekly Engagement Log'!A:A,A2),"") | N2: =IFERROR(IF(M2="","",TODAY()-M2),"") | O2: =IFERROR(IF(OR(J2="Completed",J2="Withdrawn",J2="Paused"),"—",IF(N2="","No data",IF(N2<7,"Green",IF(N2<14,"Amber","Red")))),"") | P2: Highly motivated, strong communicator
A3: SCH-002 | B3: Marcus Webb | C3: Marc | D3: marcus.webb@email.com | E3: 0423 456 789 | F3: 46054 | G3: =IFERROR(F3+180,"") | H3: Emma Clarke | I3: First-generation professional seeking corporate role | J3: Active | K3: Yes | L3: 46058 | M3: =IFERROR(MAXIFS('Weekly Engagement Log'!B:B,'Weekly Engagement Log'!A:A,A3),"") | N3: =IFERROR(IF(M3="","",TODAY()-M3),"") | O3: =IFERROR(IF(OR(J3="Completed",J3="Withdrawn",J3="Paused"),"—",IF(N3="","No data",IF(N3<7,"Green",IF(N3<14,"Amber","Red")))),"") | P3: Strong technical background, needs confidence building
A4: SCH-003 | B4: Aisha Okonkwo | C4: Aisha | D4: aisha.okonkwo@email.com | E4: 0434 567 890 | F4: 46068 | G4: =IFERROR(F4+180,"") | H4: James Hartley | I4: Redundancy, needs rapid re-entry support | J4: At-Risk | K4: No | M4: =IFERROR(MAXIFS('Weekly Engagement Log'!B:B,'Weekly Engagement Log'!A:A,A4),"") | N4: =IFERROR(IF(M4="","",TODAY()-M4),"") | O4: =IFERROR(IF(OR(J4="Completed",J4="Withdrawn",J4="Paused"),"—",IF(N4="","No data",IF(N4<7,"Green",IF(N4<14,"Amber","Red")))),"") | P4: Has missed last 2 check-ins

Sheet Onboarding & Agreement
A1: Onboarding & Agreement Milestone Tracker
A2: Recipient ID | B2: Recipient Name | C2: Milestone | D2: Date Completed | E2: Completed By | F2: Notes | G2: Status
A3: SCH-001 | B3: Jane Thompson | C3: Application received | D3: 46032 | E3: Program Team | G3: Complete
A4: SCH-001 | B4: Jane Thompson | C4: Application reviewed | D4: 46033 | E4: Program Team | G4: Complete
A5: SCH-001 | B5: Jane Thompson | C5: Scholarship offered | D5: 46034 | E5: Program Team | G5: Complete
A6: SCH-001 | B6: Jane Thompson | C6: Agreement sent | D6: 46035 | E6: Program Team | G6: Complete
A7: SCH-001 | B7: Jane Thompson | C7: Agreement signed | D7: 46042 | E7: Program Team | G7: Complete
A8: SCH-001 | B8: Jane Thompson | C8: Welcome email sent | D8: 46043 | E8: Program Team | G8: Complete
A9: SCH-001 | B9: Jane Thompson | C9: Intro/welcome call booked | D9: 46044 | E9: Program Team | G9: Complete
A10: SCH-001 | B10: Jane Thompson | C10: Intro/welcome call completed | D10: 46047 | E10: Program Team | G10: Complete
A11: SCH-001 | B11: Jane Thompson | C11: Portal access set up | D11: 46048 | E11: Program Team | G11: Complete
A12: SCH-001 | B12: Jane Thompson | C12: First group session attended | D12: 46056 | E12: Program Team | G12: Complete
A13: SCH-001 | B13: Jane Thompson | C13: First 1:1 session | G13: Pending
A14: SCH-001 | B14: Jane Thompson | C14: First module completed | G14: Pending
A15: SCH-001 | B15: Jane Thompson | C15: First reflection submitted | G15: Pending
A16: SCH-001 | B16: Jane Thompson | C16: 30-day check-in completed | G16: Pending
A17: SCH-001 | B17: Jane Thompson | C17: 60-day check-in completed | G17: Pending
A18: SCH-001 | B18: Jane Thompson | C18: 90-day check-in completed | G18: Pending
A19: SCH-002 | B19: Marcus Webb | C19: Application received | D19: 46054 | E19: Program Team | G19: Complete
A20: SCH-002 | B20: Marcus Webb | C20: Application reviewed | D20: 46055 | E20: Program Team | G20: Complete
A21: SCH-002 | B21: Marcus Webb | C21: Scholarship offered | D21: 46056 | E21: Program Team | G21: Complete
A22: SCH-002 | B22: Marcus Webb | C22: Agreement sent | D22: 46057 | E22: Program Team | G22: Complete
A23: SCH-002 | B23: Marcus Webb | C23: Agreement signed | D23: 46058 | E23: Program Team | G23: Complete
A24: SCH-002 | B24: Marcus Webb | C24: Welcome email sent | D24: 46059 | E24: Program Team | G24: Complete
A25: SCH-002 | B25: Marcus Webb | C25: Intro/welcome call booked | D25: 46060 | E25: Program Team | G25: Complete
A26: SCH-002 | B26: Marcus Webb | C26: Intro/welcome call completed | D26: 46063 | E26: Program Team | G26: Complete
A27: SCH-002 | B27: Marcus Webb | C27: Portal access set up | G27: Pending
A28: SCH-002 | B28: Marcus Webb | C28: First group session attended | G28: Pending
A29: SCH-002 | B29: Marcus Webb | C29: First 1:1 session | G29: Pending
A30: SCH-002 | B30: Marcus Webb | C30: First module completed | G30: Pending
A31: SCH-002 | B31: Marcus Webb | C31: First reflection submitted | G31: Pending
A32: SCH-002 | B32: Marcus Webb | C32: 30-day check-in completed | G32: Pending
A33: SCH-002 | B33: Marcus Webb | C33: 60-day check-in completed | G33: Pending
A34: SCH-002 | B34: Marcus Webb | C34: 90-day check-in completed | G34: Pending
A35: SCH-003 | B35: Aisha Okonkwo | C35: Application received | D35: 46068 | E35: Program Team | G35: Complete
A36: SCH-003 | B36: Aisha Okonkwo | C36: Application reviewed | D36: 46069 | E36: Program Team | G36: Complete
A37: SCH-003 | B37: Aisha Okonkwo | C37: Scholarship offered | D37: 46070 | E37: Program Team | G37: Complete
A38: SCH-003 | B38: Aisha Okonkwo | C38: Agreement sent | D38: 46071 | E38: Program Team | G38: Complete
A39: SCH-003 | B39: Aisha Okonkwo | C39: Agreement signed | G39: Complete
A40: SCH-003 | B40: Aisha Okonkwo | C40: Welcome email sent | G40: Pending
...

Sheet Weekly Engagement Log
A1: Recipient ID | B1: Week Starting (Monday) | C1: Sessions Attended This Week | D1: Hours Self-Directed Work | E1: Modules Completed | F1: Applications Submitted | G1: Reflections Submitted | H1: Coach Outreach Sent | I1: Recipient Outreach Received | J1: Engagement Score | K1: Met Minimum Commitment? | L1: Coach Comment | M1: Flag for Follow-Up?
A2: SCH-001 | B2: 46147 | C2: 2 | D2: 3 | E2: 1 | F2: 2 | G2: 1 | H2: No | I2: Yes | J2: =IFERROR(IF(C2>=1,2,0)+IF(D2>=2,1,0)+IF((E2+F2+G2)>=1,1,0)+IF(I2="Yes",1,0),"") | K2: =IFERROR(IF(AND(C2>=1,D2>=2),"Yes","No"),"") | L2: Strong week - submitted 2 applications | M2: No
A3: SCH-001 | B3: 46154 | C3: 1 | D3: 2 | E3: 0 | F3: 1 | G3: 1 | H3: No | I3: No | J3: =IFERROR(IF(C3>=1,2,0)+IF(D3>=2,1,0)+IF((E3+F3+G3)>=1,1,0)+IF(I3="Yes",1,0),"") | K3: =IFERROR(IF(AND(C3>=1,D3>=2),"Yes","No"),"") | L3: Steady progress | M3: No
A4: SCH-002 | B4: 46147 | C4: 1 | D4: 2 | E4: 2 | F4: 0 | G4: 1 | H4: No | I4: No | J4: =IFERROR(IF(C4>=1,2,0)+IF(D4>=2,1,0)+IF((E4+F4+G4)>=1,1,0)+IF(I4="Yes",1,0),"") | K4: =IFERROR(IF(AND(C4>=1,D4>=2),"Yes","No"),"") | L4: Good module completion rate | M4: No
A5: SCH-002 | B5: 46154 | C5: 2 | D5: 4 | E5: 1 | F5: 1 | G5: 0 | H5: No | I5: Yes | J5: =IFERROR(IF(C5>=1,2,0)+IF(D5>=2,1,0)+IF((E5+F5+G5)>=1,1,0)+IF(I5="Yes",1,0),"") | K5: =IFERROR(IF(AND(C5>=1,D5>=2),"Yes","No"),"") | L5: Excellent engagement this week | M5: No
A6: SCH-003 | B6: 46147 | C6: 0 | D6: 0 | E6: 0 | F6: 0 | G6: 0 | H6: Yes | I6: No | J6: =IFERROR(IF(C6>=1,2,0)+IF(D6>=2,1,0)+IF((E6+F6+G6)>=1,1,0)+IF(I6="Yes",1,0),"") | K6: =IFERROR(IF(AND(C6>=1,D6>=2),"Yes","No"),"") | L6: No engagement - outreach sent | M6: Yes
A7: SCH-003 | B7: 46154 | C7: 0 | D7: 1 | E7: 0 | F7: 0 | G7: 0 | H7: Yes | I7: No | J7: =IFERROR(IF(C7>=1,2,0)+IF(D7>=2,1,0)+IF((E7+F7+G7)>=1,1,0)+IF(I7="Yes",1,0),"") | K7: =IFERROR(IF(AND(C7>=1,D7>=2),"Yes","No"),"") | L7: Minimal engagement - follow up required | M7: Yes

Sheet Session Log
A1: Date | B1: Recipient ID | C1: Session Type | D1: Coach | E1: Duration (min) | F1: Attended? | G1: Topic | H1: Key Takeaways | I1: Action Items Set | J1: Action Items Status
A2: 46148 | B2: SCH-001 | C2: Group | D2: Sarah Mitchell | E2: 90 | F2: Yes | G2: Resume Masterclass | H2: Learned to tailor resume for ATS | I2: Update summary section and skills list | J2: Done
A3: 46148 | B3: SCH-002 | C3: Group | D3: Sarah Mitchell | E3: 90 | F3: Yes | G3: Resume Masterclass | H3: Strong structure already in place | I3: Add quantified achievements | J3: Partial
A4: 46148 | B4: SCH-003 | C4: Group | D4: James Hartley | E4: 90 | F4: No | G4: Resume Masterclass | I4: Follow up on attendance | J4: Not Done
A5: 46149 | B5: SCH-001 | C5: 1:1 | D5: Sarah Mitchell | E5: 45 | F5: Yes | G5: Career direction clarity | H5: Identified 3 target roles | I5: Research job descriptions for each role | J5: Done
A6: 46150 | B6: SCH-002 | C6: 1:1 | D6: Emma Clarke | E6: 45 | F6: Yes | G6: Salary benchmarking | H6: Clarified market rate expectations | I6: Complete salary research template | J6: Partial
A7: 46155 | B7: SCH-001 | C7: Group | D7: Sarah Mitchell | E7: 90 | F7: Yes | G7: Interview Prep | H7: Practised STAR method responses | I7: Record practice answers | J7: Not Done

Sheet Activity Log
A1: Date | B1: Recipient ID | C1: Activity Type | D1: Activity Name | E1: Status | F1: Time Spent (min) | G1: Coach Feedback Given? | H1: Coach Feedback Date | I1: Notes
A2: 46147 | B2: SCH-001 | C2: Module | D2: Winning Applicants Formula | E2: Completed | F2: 45 | G2: Yes | H2: 46148 | I2: Great engagement with content
A3: 46147 | B3: SCH-002 | C3: Module | D3: Career Blueprint Builder | E3: Completed | F3: 60 | G3: No | I3: Self-directed completion
A4: 46148 | B4: SCH-001 | C4: Application | D4: Senior Project Manager - City Council | E4: Completed | F4: 120 | G4: No | I4: Tailored cover letter included
A5: 46149 | B5: SCH-002 | C5: Reflection | D5: Week 1 Reflection | E5: Completed | F5: 30 | G5: Yes | H5: 46150 | I5: Insightful reflection on barriers
A6: 46150 | B6: SCH-003 | C6: Module | D6: Reset Your Mindset | E6: Started | F6: 20 | G6: No | I6: Did not complete - flagged
A7: 46152 | B7: SCH-001 | C7: Application | D7: Communications Manager - DHHS | E7: Completed | F7: 90 | G7: No | I7: Second application this week

Sheet Coach Notes & Wellbeing Flags
A1: CONFIDENTIAL — For coaching team use only. Do not share with recipients.
A2: Date | B2: Recipient ID | C2: Note Type | D2: Note (Confidential) | E2: Flag for Team Review? | F2: Action Needed | G2: Resolved? | H2: Resolution Date
A3: 46148 | B3: SCH-001 | C3: Win | D3: Jane secured an interview for a role she applied to independently before joining the program. Huge confidence boost. | E3: No | G3: Yes | H3: 46149
A4: 46149 | B4: SCH-002 | C4: Coaching observation | D4: Marcus shows strong technical knowledge but struggles with self-advocacy in mock interviews. Focus 1:1 time here. | E4: No | F4: Dedicate next 1:1 to confidence + storytelling | G4: No
A5: 46150 | B5: SCH-003 | C5: Wellbeing | D5: Aisha disclosed she is experiencing financial stress related to her redundancy. May impact engagement. | E5: Yes | F5: Check in personally this week - consider flexibility options | G5: No
A6: 46151 | B6: SCH-003 | C6: Concern | D6: No response to 2 outreach attempts. Risk of early withdrawal. | E6: Yes | F6: Escalate to program lead if no response by 16 May | G6: No
A7: 46152 | B7: SCH-001 | C7: Coaching observation | D7: Jane is progressing faster than expected. Consider whether she needs stretch goals added to her plan. | E7: No | F7: Discuss in next supervision | G7: No

Sheet Withdrawal Risk Monitor
A1: VIEW ONLY — Auto-populated from Recipient Profile and Weekly Engagement Log. Do not edit.
A2: Recipient ID | B2: Recipient Name | C2: Days Since Last Engagement | D2: Last Week Engagement Score | E2: Risk Level | F2: Outreach Attempts (Last 14 days) | G2: Last Outreach Date | H2: Recommended Action | I2: Status | J2: Owner
A3: =IF('Recipient Profile'!A2<>"", 'Recipient Profile'!A2, "") | B3: ='Recipient Profile'!B2 | C3: ='Recipient Profile'!N2 | D3: 4 | E3: ='Recipient Profile'!O2 | F3: 0 | H3: =IF(E3="Red","Begin withdrawal conversation per agreement clause 3",IF(E3="Amber","Send check-in message — warm tone",IF(E3="Green","On track — continue normal cadence","—"))) | I3: Acknowledged | J3: Sarah Mitchell
A4: =IF('Recipient Profile'!A3<>"", 'Recipient Profile'!A3, "") | B4: ='Recipient Profile'!B3 | C4: ='Recipient Profile'!N3 | D4: 4 | E4: ='Recipient Profile'!O3 | F4: 0 | H4: =IF(E4="Red","Begin withdrawal conversation per agreement clause 3",IF(E4="Amber","Send check-in message — warm tone",IF(E4="Green","On track — continue normal cadence","—"))) | I4: Acknowledged | J4: Emma Clarke
A5: =IF('Recipient Profile'!A4<>"", 'Recipient Profile'!A4, "") | B5: ='Recipient Profile'!B4 | C5: ='Recipient Profile'!N4 | D5: 0 | E5: ='Recipient Profile'!O4 | F5: 2 | G5: 46154 | H5: =IF(E5="Red","Begin withdrawal conversation per agreement clause 3",IF(E5="Amber","Send check-in message — warm tone",IF(E5="Green","On track — continue normal cadence","—"))) | I5: In Conversation | J5: James Hartley

Sheet Communications Log
A1: Date | B1: Recipient ID | C1: Direction | D1: Channel | E1: Sender | F1: Subject / Summary | G1: Response Received? | H1: Response Date | I1: Notes
A2: 46148 | B2: SCH-001 | C2: Outbound | D2: Email | E2: Sarah Mitchell | F2: Welcome to the CAP Scholarship Program — next steps inside | G2: Yes | H2: 46148 | I2: Jane responded enthusiastically within the hour
A3: 46150 | B3: SCH-003 | C3: Outbound | D3: Email | E3: James Hartley | F3: Checking in — we missed you at group coaching this week | G3: No | I3: No response received
A4: 46152 | B4: SCH-003 | C4: Outbound | D4: DM | E4: James Hartley | F4: Hey Aisha — just wanted to check in and see how you're going | G4: No | I4: Sent via community platform
A5: 46153 | B5: SCH-002 | C5: Inbound | D5: Email | E5: Emma Clarke | F5: Question about resume review submission process | G5: Yes | H5: 46153 | I5: Replied with booking link and instructions
A6: 46154 | B6: SCH-001 | C6: Inbound | D6: DM | E6: Sarah Mitchell | F6: Exciting news — got an interview! | G6: Yes | H6: 46154 | I6: Jane shared great news - logged in Coach Notes too

Sheet Reference Data
A1: Coach Names | B1: Stage Values | C1: Note Types | D1: Channel Types | E1: Direction | F1: Session Types | G1: Activity Types | H1: Status Options | I1: Risk Level | J1: Yes/No | K1: Attended Options | L1: Action Status | M1: Outreach Status
A2: Sarah Mitchell | B2: Onboarding | C2: Wellbeing | D2: Email | E2: Outbound | F2: Group | G2: Module | H2: Started | I2: Green | J2: Yes | K2: Yes | L2: Done | M2: Acknowledged
A3: Emma Clarke | B3: Active | C3: Circumstance | D3: SMS | E3: Inbound | F3: 1:1 | G3: Application | H3: Completed | I3: Amber | J3: No | K3: No | L3: Partial | M3: In Conversation
A4: James Hartley | B4: At-Risk | C4: Coaching observation | D4: DM | F4: Drop-in | G4: Reflection | H4: Stuck | I4: Red | K4: Late | L4: Not Done | M4: Resolved
A5: Priya Nair | B5: Paused | C5: Personal disclosure | D5: Voice | F5: Workshop | G5: Task | H5: Done | I5: — | K5: Left Early | M5: Escalating to withdrawal
B6: Completed | C6: Win | D6: In-person | G6: Resource Accessed | H6: Partial
B7: Withdrawn | C7: Concern | H7: Not Done
